import React from 'react';
import { render, screen, fireEvent } from '@testing-library/react';
import '@testing-library/jest-dom';
import { ErrorBoundary, withErrorBoundary } from './error-boundary';
import { SectionErrorBoundary } from './section-error-boundary';

// Component that throws an error for testing
const ThrowError = ({ shouldThrow = false }: { shouldThrow?: boolean }) => {
  if (shouldThrow) {
    throw new Error('Test error');
  }
  return <div>No error</div>;
};

describe('ErrorBoundary', () => {
  // Suppress console.error for tests
  const originalError = console.error;
  beforeAll(() => {
    console.error = jest.fn();
  });
  afterAll(() => {
    console.error = originalError;
  });

  it('should render children when there is no error', () => {
    render(
      <ErrorBoundary>
        <ThrowError shouldThrow={false} />
      </ErrorBoundary>
    );

    expect(screen.getByText('No error')).toBeInTheDocument();
  });

  it('should render error UI when child component throws', () => {
    render(
      <ErrorBoundary>
        <ThrowError shouldThrow={true} />
      </ErrorBoundary>
    );

    expect(screen.getByText('Something went wrong')).toBeInTheDocument();
    expect(screen.getByText('Try Again')).toBeInTheDocument();
    expect(screen.getByText('Reload Page')).toBeInTheDocument();
  });

  it('should render custom fallback when provided', () => {
    const customFallback = <div>Custom error message</div>;

    render(
      <ErrorBoundary fallback={customFallback}>
        <ThrowError shouldThrow={true} />
      </ErrorBoundary>
    );

    expect(screen.getByText('Custom error message')).toBeInTheDocument();
    expect(screen.queryByText('Something went wrong')).not.toBeInTheDocument();
  });

  it('should call onError callback when error occurs', () => {
    const onError = jest.fn();

    render(
      <ErrorBoundary onError={onError}>
        <ThrowError shouldThrow={true} />
      </ErrorBoundary>
    );

    expect(onError).toHaveBeenCalledWith(
      expect.any(Error),
      expect.objectContaining({
        componentStack: expect.any(String),
      })
    );
  });

  it('should reset error state when Try Again is clicked', () => {
    let shouldThrow = true;
    const TestComponent = () => {
      if (shouldThrow) {
        throw new Error('Test error');
      }
      return <div>No error</div>;
    };

    const { rerender } = render(
      <ErrorBoundary>
        <TestComponent />
      </ErrorBoundary>
    );

    expect(screen.getByText('Something went wrong')).toBeInTheDocument();

    // Simulate fixing the error condition and retrying
    shouldThrow = false;
    fireEvent.click(screen.getByText('Try Again'));

    // The error boundary should reset and re-render children
    rerender(
      <ErrorBoundary>
        <TestComponent />
      </ErrorBoundary>
    );

    expect(screen.getByText('No error')).toBeInTheDocument();
  });
});

describe('SectionErrorBoundary', () => {
  const originalError = console.error;
  beforeAll(() => {
    console.error = jest.fn();
  });
  afterAll(() => {
    console.error = originalError;
  });

  it('should render children when there is no error', () => {
    render(
      <SectionErrorBoundary sectionName='test section'>
        <div>Section content</div>
      </SectionErrorBoundary>
    );

    expect(screen.getByText('Section content')).toBeInTheDocument();
  });

  it('should render section-specific error UI when child component throws', () => {
    render(
      <SectionErrorBoundary sectionName='test section'>
        <ThrowError shouldThrow={true} />
      </SectionErrorBoundary>
    );

    expect(screen.getByText('Unable to load test section')).toBeInTheDocument();
    expect(screen.getByText('Retry')).toBeInTheDocument();
  });

  it('should hide retry button when showRetry is false', () => {
    render(
      <SectionErrorBoundary sectionName='test section' showRetry={false}>
        <ThrowError shouldThrow={true} />
      </SectionErrorBoundary>
    );

    expect(screen.getByText('Unable to load test section')).toBeInTheDocument();
    expect(screen.queryByText('Retry')).not.toBeInTheDocument();
  });
});

describe('withErrorBoundary HOC', () => {
  const originalError = console.error;
  beforeAll(() => {
    console.error = jest.fn();
  });
  afterAll(() => {
    console.error = originalError;
  });

  it('should wrap component with error boundary', () => {
    const WrappedComponent = withErrorBoundary(ThrowError);

    render(<WrappedComponent shouldThrow={false} />);

    expect(screen.getByText('No error')).toBeInTheDocument();
  });

  it('should catch errors in wrapped component', () => {
    const WrappedComponent = withErrorBoundary(ThrowError);

    render(<WrappedComponent shouldThrow={true} />);

    expect(screen.getByText('Something went wrong')).toBeInTheDocument();
  });

  it('should use custom fallback when provided', () => {
    const customFallback = <div>HOC custom error</div>;
    const WrappedComponent = withErrorBoundary(ThrowError, customFallback);

    render(<WrappedComponent shouldThrow={true} />);

    expect(screen.getByText('HOC custom error')).toBeInTheDocument();
  });
});
